Workbook

Sheet Показатели рентабельности
A3: Отрасль 1. Технологии и полупроводники. | H3: Отрасль 2. Потребительский discretionary, e-commerce и онлайн-сервисы. | P3: Отрасль 3. Коммуникационные сервисы, digital-реклама и подписки. | X3: Отрасль 4. Здравоохранение, биотехнологии и медицинские технологии. | AF3: Отрасль 5. Потребительские товары повседневного спроса.
A6: 1 | B6: ROE | H6: 1 | I6: ROE | P6: 1 | Q6: ROE | X6: 1 | Y6: ROE | AF6: 1 | AG6: ROE
B7: Тикер | C7: 2024 | D7: 2023 | E7: 2022 | I7: Тикер | J7: 2024 | K7: 2023 | L7: 2022 | Q7: Тикер | R7: 2024 | S7: 2023 | T7: 2022 | Y7: Тикер | Z7: 2024 | AA7: 2023 | AB7: 2022 | AG7: Тикер | AH7: 2024 | AI7: 2023 | AJ7: 2022
A8: 1 | B8: AAPL | C8: =ROE!D2 -> 1.5741251 | D8: =ROE!C2 -> 1.7194951 | E8: =ROE!B2 -> 1.9695887 | H8: 1 | I8: AMZN | J8: =ROE!D5 -> 0.24289682 | K8: =ROE!C5 -> 0.17489753 | L8: =ROE!B5 -> -0.018638346 | P8: 1 | Q8: GOOGL | R8: =ROE!D11 -> 0.32908492 | S8: =ROE!C11 -> 0.27355646 | T8: =ROE!B11 -> 0.23413392 | X8: 1 | Y8: AMGN | Z8: =ROE!D4 -> 0.6755306 | AA8: =ROE!C4 -> 1.3579298 | AB8: =ROE!B4 -> 1.789675 | AF8: 1 | AG8: COST | AH8: =ROE!D9 -> 0.3026705 | AI8: =ROE!C9 -> 0.27536105 | AJ8: =ROE!B9 -> 0.2831121
A9: 2 | B9: MSFT | C9: =ROE!D16 -> 0.37133347 | D9: =ROE!C16 -> 0.38823924 | E9: =ROE!B16 -> 0.43675469 | H9: 2 | I9: MELI | J9: =ROE!D14 -> 0.51495554 | K9: =ROE!C14 -> 0.40302164 | L9: =ROE!B14 -> 0.26382047 | P9: 2 | Q9: META | R9: =ROE!D15 -> 0.37140602 | S9: =ROE!C15 -> 0.280392 | T9: =ROE!B15 -> 0.18454734 | X9: 2 | Y9: REGN | Z9: =ROE!D20 -> 0.15951069 | AA9: =ROE!C20 -> 0.16257548 | AB9: =ROE!B20 -> 0.19142252 | AF9: 2 | AG9: PEP | AH9: =ROE!D19 -> 0.52419002 | AI9: =ROE!C19 -> 0.50903175 | AJ9: =ROE!B19 -> 0.51956382
A10: 3 | B10: ASML | C10: =ROE!D6 -> 0.47427433 | D10: =ROE!C6 -> 0.70421143 | E10: =ROE!B6 -> 0.63833023 | H10: 3 | I10: TSLA | J10: =ROE!D22 -> 0.10520336 | K10: =ROE!C22 -> 0.27947232 | L10: =ROE!B22 -> 0.28147369 | P10: 3 | Q10: NFLX | R10: =ROE!D17 -> 0.38434898 | S10: =ROE!C17 -> 0.2614721 | T10: =ROE!B17 -> 0.21619278 | X10: 3 | Y10: GILD | Z10: =ROE!D10 -> 0.022768778 | AA10: =ROE!C10 -> 0.25707349 | AB10: =ROE!B10 -> 0.21619586 | AF10: 3 | AG10: MDLZ | AH10: =ROE!D13 -> 0.16687174 | AI10: =ROE!C13 -> 0.1796251 | AJ10: =ROE!B13 -> 0.10106759
A11: 4 | B11: AMD | C11: =ROE!D3 -> 0.028926494 | D11: =ROE!C3 -> 0.015437176 | E11: =ROE!B3 -> 0.024109589 | H11: 4 | I11: PDD | J11: =ROE!D18 -> 0.44923963 | K11: =ROE!C18 -> 0.39360053 | L11: =ROE!B18 -> 0.26779161 | P11: 4 | Q11: TMUS | R11: =ROE!D21 -> 0.1793351 | S11: =ROE!C21 -> 0.12379159 | T11: =ROE!B21 -> 0.037182727 | X11: 4 | Y11: VRTX | Z11: =ROE!D23 -> -0.031515152 | AA11: =ROE!C23 -> 0.22986622 | AB11: =ROE!B23 -> 0.23877464 | AF11: 4 | AG11: KDP | AH11: =ROE!D12 -> 0.057733528 | AI11: =ROE!C12 -> 0.085862761 | AJ11: =ROE!B12 -> 0.057151954
P12: 5 | Q12: CHTR | R12: =ROE!D8 -> 0.38113448 | S12: =ROE!C8 -> 0.45107647 | T12: =ROE!B8 -> 0.5543371 | AF12: 5 | AG12: CCEP | AH12: =ROE!D7 -> 0.17224415 | AI12: =ROE!C7 -> 0.21643001 | AJ12: =ROE!B7 -> 0.20249765
A14: 2 | B14: ROA | H14: 2 | I14: ROA | P14: 2 | Q14: ROA | X14: 2 | Y14: ROA | AF14: 2 | AG14: ROA
C15: 2024 | D15: 2023 | E15: 2022 | J15: 2024 | K15: 2023 | L15: 2022 | R15: 2024 | S15: 2023 | T15: 2022 | Z15: 2024 | AA15: 2023 | AB15: 2022 | AH15: 2024 | AI15: 2023 | AJ15: 2022
A16: 1 | B16: AAPL | C16: =ROA!D2 -> 0.26126208 | D16: =ROA!C2 -> 0.27503126 | E16: =ROA!B2 -> 0.28292441 | H16: 1 | I16: AMZN | J16: =ROA!D5 -> 0.10279437 | K16: =ROA!C5 -> 0.061431821 | L16: =ROA!B5 -> -0.0058831793 | P16: 1 | Q16: GOOGL | R16: =ROA!D11 -> 0.23484017 | S16: =ROA!C11 -> 0.1922606 | T16: =ROA!B11 -> 0.16418809 | X16: 1 | Y16: AMGN | Z16: =ROA!D4 -> 0.043282026 | AA16: =ROA!C4 -> 0.082785395 | AB16: =ROA!B4 -> 0.10061271 | AF16: 1 | AG16: COST | AH16: =ROA!D9 -> 0.10613362 | AI16: =ROA!C9 -> 0.094502854 | AJ16: =ROA!B9 -> 0.091076271
A17: 2 | B17: MSFT | C17: =ROA!D16 -> 0.19074187 | D17: =ROA!C16 -> 0.18630152 | E17: =ROA!B16 -> 0.19936959 | H17: 2 | I17: MELI | J17: =ROA!D14 -> 0.089282377 | K17: =ROA!C14 -> 0.062970524 | L17: =ROA!B14 -> 0.035090274 | P17: 2 | Q17: META | R17: =ROA!D15 -> 0.24663965 | S17: =ROA!C15 -> 0.18826532 | T17: =ROA!B15 -> 0.12491453 | X17: 2 | Y17: REGN | Z17: =ROA!D20 -> 0.12458004 | AA17: =ROA!C20 -> 0.12693215 | AB17: =ROA!B20 -> 0.1485016 | AF17: 2 | AG17: PEP | AH17: =ROA!D19 -> 0.095798202 | AI17: =ROA!C19 -> 0.094186276 | AJ17: =ROA!B19 -> 0.096651372 | AL17: =ROE!AL4 | AM17: =ROE!AM4 | AN17: =ROE!AN4
A18: 3 | B18: ASML | C18: =ROA!D6 -> 0.17101859 | D18: =ROA!C6 -> 0.20559181 | E18: =ROA!B6 -> 0.15493493 | H18: 3 | I18: TSLA | J18: =ROA!D22 -> 0.062355699 | K18: =ROA!C22 -> 0.15875654 | L18: =ROA!B22 -> 0.1528213 | P18: 3 | Q18: NFLX | R18: =ROA!D17 -> 0.1702116 | S18: =ROA!C17 -> 0.11113059 | T18: =ROA!B17 -> 0.092436371 | X18: 3 | Y18: GILD | Z18: =ROA!D10 -> 0.0079260238 | AA18: =ROA!C10 -> 0.090425872 | AB18: =ROA!B10 -> 0.072691583 | AF18: 3 | AG18: MDLZ | AH18: =ROA!D13 -> 0.065924168 | AI18: =ROA!C13 -> 0.069574611 | AJ18: =ROA!B13 -> 0.038181026 | AL18: =ROE!AL18 | AM18: =ROE!AM18 | AN18: =ROE!AN18
A19: 4 | B19: AMD | C19: =ROA!D3 -> 0.02393681 | D19: =ROA!C3 -> 0.012608423 | E19: =ROA!B3 -> 0.019532406 | H19: 4 | I19: PDD | J19: =ROA!D18 -> 0.26358662 | K19: =ROA!C18 -> 0.20514949 | L19: =ROA!B18 -> 0.13300467 | P19: 4 | Q19: TMUS | R19: =ROA!D21 -> 0.054551534 | S19: =ROA!C21 -> 0.039697389 | T19: =ROA!B21 -> 0.01225525 | X19: 4 | Y19: VRTX | Z19: =ROA!D23 -> -0.02366592 | AA19: =ROA!C23 -> 0.17707938 | AB19: =ROA!B23 -> 0.18302123 | AF19: 4 | AG19: KDP | AH19: =ROA!D12 -> 0.027302008 | AI19: =ROA!C12 -> 0.041955621 | AJ19: =ROA!B12 -> 0.02770222 | AL19: =ROE!AL5 | AM19: =ROE!AM5 | AN19: =ROE!AN5
P20: 5 | Q20: CHTR | R20: =ROA!D8 -> 0.034204426 | S20: =ROA!C8 -> 0.031242716 | T20: =ROA!B8 -> 0.034977132 | AF20: 5 | AG20: CCEP | AH20: =ROA!D7 -> 0.046989429 | AI20: =ROA!C7 -> 0.056994553 | AJ20: =ROA!B7 -> 0.051444751 | AL20: =ROE!AL8 | AM20: =ROE!AM8 | AN20: =ROE!AN8
A22: 3 | B22: ROIC | H22: 3 | I22: ROIC | P22: 3 | Q22: ROIC | X22: 3 | Y22: ROIC | AF22: 3 | AG22: ROIC
B23: Тикер | C23: 2024 | D23: 2023 | E23: 2022 | I23: Тикер | J23: 2024 | K23: 2023 | L23: 2022 | Q23: Тикер | R23: 2024 | S23: 2023 | T23: 2022 | Y23: Тикер | Z23: 2024 | AA23: 2023 | AB23: 2022 | AG23: Тикер | AH23: 2024 | AI23: 2023 | AJ23: 2022
A24: 1 | B24: AAPL | C24: =ROIC!D2 -> 0.5717837 | D24: =ROIC!C2 -> 0.56268883 | E24: =ROIC!B2 -> 0.5861678 | H24: 1 | I24: AMZN | J24: =ROIC!D5 -> 0.16570278 | K24: =ROIC!C5 -> 0.12369397 | L24: =ROIC!B5 -> -0.013225153 | P24: 1 | Q24: GOOGL | R24: =ROIC!D11 -> 0.29866607 | S24: =ROIC!C11 -> 0.25083967 | T24: =ROIC!B11 -> 0.22405925 | X24: 1 | Y24: AMGN | Z24: =ROIC!D4 -> 0.1044278 | AA24: =ROIC!C4 -> 0.12951488 | AB24: =ROIC!B4 -> 0.18321436 | AF24: 1 | AG24: COST | AH24: =ROIC!D9 -> 0.25478739 | AI24: =ROIC!C9 -> 0.2034084 | AJ24: =ROIC!B9 -> 0.22185394
A25: 2 | B25: MSFT | C25: =ROIC!D16 -> 0.28283015 | D25: =ROIC!C16 -> 0.29178372 | E25: =ROIC!B16 -> 0.34453327 | H25: 2 | I25: MELI | J25: =ROIC!D14 -> 0.20521446 | K25: =ROIC!C14 -> 0.14717533 | L25: =ROIC!B14 -> 0.086535518 | P25: 2 | Q25: META | R25: =ROIC!D15 -> 0.29788184 | S25: =ROIC!C15 -> 0.23004941 | T25: =ROIC!B15 -> 0.17214404 | X25: 2 | Y25: REGN | Z25: =ROIC!D20 -> 0.14243277 | AA25: =ROIC!C20 -> 0.1438807 | AB25: =ROIC!B20 -> 0.17818489 | AF25: 2 | AG25: PEP | AH25: =ROIC!D19 -> 0.16627141 | AI25: =ROIC!C19 -> 0.15671696 | AJ25: =ROIC!B19 -> 0.17370179
A26: 3 | B26: ASML | C26: =ROIC!D6 -> 0.32352142 | D26: =ROIC!C6 -> 0.43000792 | E26: =ROIC!B6 -> 0.42366929 | H26: 3 | I26: TSLA | J26: =ROIC!D22 -> 0.091984028 | K26: =ROIC!C22 -> 0.22600685 | L26: =ROIC!B22 -> 0.27299493 | P26: 3 | Q26: NFLX | R26: =ROIC!D17 -> 0.2316083 | S26: =ROIC!C17 -> 0.17250553 | T26: =ROIC!B17 -> 0.14501834 | X26: 3 | Y26: GILD | Z26: =ROIC!D10 -> 0.025134907 | AA26: =ROIC!C10 -> 0.13350849 | AB26: =ROIC!B10 -> 0.11405849 | AF26: 3 | AG26: MDLZ | AH26: =ROIC!D13 -> 0.11595106 | AI26: =ROIC!C13 -> 0.099481211 | AJ26: =ROIC!B13 -> 0.0537239
A27: 4 | B27: AMD | C27: =ROIC!D3 -> 0.028375872 | D27: =ROIC!C3 -> 0.017452788 | E27: =ROIC!B3 -> 0.024521865 | H27: 4 | I27: PDD | J27: =ROIC!D18 -> 0.35282257 | K27: =ROIC!C18 -> 0.31103696 | L27: =ROIC!B18 -> 0.23821755 | P27: 4 | Q27: TMUS | R27: =ROIC!D21 -> 0.099766901 | S27: =ROIC!C21 -> 0.077567879 | T27: =ROIC!B21 -> 0.037845105 | X27: 4 | Y27: VRTX | Z27: =ROIC!D23 -> -0.036658612 | AA27: =ROIC!C23 -> 0.20796146 | AB27: =ROIC!B23 -> 0.24186624 | AF27: 4 | AG27: KDP | AH27: =ROIC!D12 -> 0.050113377 | AI27: =ROIC!C12 -> 0.066209749 | AJ27: =ROIC!B12 -> 0.054282691
P28: 5 | Q28: CHTR | R28: =ROIC!D8 -> 0.089201829 | S28: =ROIC!C8 -> 0.084576624 | T28: =ROIC!B8 -> 0.088268271 | AF28: 5 | AG28: CCEP | AH28: =ROIC!D7 -> 0.084998954 | AI28: =ROIC!C7 -> 0.095917116 | AJ28: =ROIC!B7 -> 0.088173681
A30: 4 | B30: Margin | H30: 4 | I30: Margin | P30: 4 | Q30: Margin | X30: 4 | Y30: Margin | AF30: 4 | AG30: Margin
B31: Тикер | C31: 2024 | D31: 2023 | E31: 2022 | I31: Тикер | J31: 2024 | K31: 2023 | L31: 2022 | Q31: Тикер | R31: 2024 | S31: 2023 | T31: 2022 | Y31: Тикер | Z31: 2024 | AA31: 2023 | AB31: 2022 | AG31: Тикер | AH31: 2024 | AI31: 2023 | AJ31: 2022
A32: 1 | B32: AAPL | C32: ='Net Profit Margin'!D2 -> 0.23971256 | D32: ='Net Profit Margin'!C2 -> 0.25306234 | E32: ='Net Profit Margin'!B2 -> 0.25309641 | H32: 1 | I32: AMZN | J32: ='Net Profit Margin'!D5 -> 0.092871172 | K32: ='Net Profit Margin'!C5 -> 0.052932836 | L32: ='Net Profit Margin'!B5 -> -0.005295895 | P32: 1 | Q32: GOOGL | R32: ='Net Profit Margin'!D11 -> 0.28603672 | S32: ='Net Profit Margin'!C11 -> 0.24006649 | T32: ='Net Profit Margin'!B11 -> 0.21203807 | X32: 1 | Y32: AMGN | Z32: ='Net Profit Margin'!D4 -> 0.12236716 | AA32: ='Net Profit Margin'!C4 -> 0.23827598 | AB32: ='Net Profit Margin'!B4 -> 0.2489078 | AF32: 1 | AG32: COST | AH32: ='Net Profit Margin'!D9 -> 0.028952302 | AI32: ='Net Profit Margin'!C9 -> 0.02596888 | AJ32: ='Net Profit Margin'!B9 -> 0.025749711
A33: 2 | B33: MSFT | C33: ='Net Profit Margin'!D16 -> 0.35955973 | D33: ='Net Profit Margin'!C16 -> 0.34146238 | E33: ='Net Profit Margin'!B16 -> 0.36686337 | H33: 2 | I33: MELI | J33: ='Net Profit Margin'!D14 -> 0.091976705 | K33: ='Net Profit Margin'!C14 -> 0.065333951 | L33: ='Net Profit Margin'!B14 -> 0.04471243 | P33: 2 | Q33: META | R33: ='Net Profit Margin'!D15 -> 0.37908584 | S33: ='Net Profit Margin'!C15 -> 0.28982521 | T33: ='Net Profit Margin'!B15 -> 0.19895548 | X33: 2 | Y33: REGN | Z33: ='Net Profit Margin'!D20 -> 0.31070272 | AA33: ='Net Profit Margin'!C20 -> 0.30140579 | AB33: ='Net Profit Margin'!B20 -> 0.35639823 | AF33: 2 | AG33: PEP | AH33: ='Net Profit Margin'!D19 -> 0.10427417 | AI33: ='Net Profit Margin'!C19 -> 0.09920084 | AJ33: ='Net Profit Margin'!B19 -> 0.10313455
A34: 3 | B34: ASML | C34: ='Net Profit Margin'!D6 -> 0.26789891 | D34: ='Net Profit Margin'!C6 -> 0.28444944 | E34: ='Net Profit Margin'!B6 -> 0.26562574 | H34: 3 | I34: TSLA | J34: ='Net Profit Margin'!D22 -> 0.072985976 | K34: ='Net Profit Margin'!C22 -> 0.15499158 | L34: ='Net Profit Margin'!B22 -> 0.15446466 | P34: 3 | Q34: NFLX | R34: ='Net Profit Margin'!D17 -> 0.22336962 | S34: ='Net Profit Margin'!C17 -> 0.16036362 | T34: ='Net Profit Margin'!B17 -> 0.14207958 | X34: 3 | Y34: GILD | Z34: ='Net Profit Margin'!D10 -> 0.01669333 | AA34: ='Net Profit Margin'!C10 -> 0.20891724 | AB34: ='Net Profit Margin'!B10 -> 0.16832228 | AF34: 3 | AG34: MDLZ | AH34: ='Net Profit Margin'!D13 -> 0.1265333 | AI34: ='Net Profit Margin'!C13 -> 0.1376888 | AJ34: ='Net Profit Margin'!B13 -> 0.086264923
A35: 4 | B35: AMD | C35: ='Net Profit Margin'!D3 -> 0.063641652 | D35: ='Net Profit Margin'!C3 -> 0.037654321 | E35: ='Net Profit Margin'!B3 -> 0.055929833 | H35: 4 | I35: PDD | J35: ='Net Profit Margin'!D18 -> 0.28548554 | K35: ='Net Profit Margin'!C18 -> 0.24239516 | L35: ='Net Profit Margin'!B18 -> 0.24156437 | P35: 4 | Q35: TMUS | R35: ='Net Profit Margin'!D21 -> 0.13929975 | S35: ='Net Profit Margin'!C21 -> 0.10587082 | T35: ='Net Profit Margin'!B21 -> 0.032549547 | X35: 4 | Y35: VRTX | Z35: ='Net Profit Margin'!D23 -> -0.0486021 | AA35: ='Net Profit Margin'!C23 -> 0.36675718 | AB35: ='Net Profit Margin'!B23 -> 0.37197532 | AF35: 4 | AG35: KDP | AH35: ='Net Profit Margin'!D12 -> 0.093870106 | AI35: ='Net Profit Margin'!C12 -> 0.1472256 | AJ35: ='Net Profit Margin'!B12 -> 0.10215551
P36: 5 | Q36: CHTR | R36: ='Net Profit Margin'!D8 -> 0.092275574 | S36: ='Net Profit Margin'!C8 -> 0.08345084 | T36: ='Net Profit Margin'!B8 -> 0.093572989 | AF36: 5 | AG36: CCEP | AH36: ='Net Profit Margin'!D7 -> 0.069380566 | AI36: ='Net Profit Margin'!C7 -> 0.091192219 | AJ36: ='Net Profit Margin'!B7 -> 0.087066975
A38: Выводы (показатели рентабельности): | H38: Выводы (показатели рентабельности): | P38: Выводы (показатели рентабельности): | X38: Выводы (показатели рентабельности): | AF38: Выводы (показатели рентабельности):
A40: По итогам анализа показателей рентабельности в группе компаний технологического и полупроводникового сектора для дальнейшего рассмотрения были отобраны Apple (AAPL) и ASML Holding (ASML). Apple занимает первое место по показателям ROE (157,41%), ROA (26,13%) и ROIC (57,18%) в 2024 году, что говорит о наиболее высокой эффективности использования собственного капитала, активов и инвестированного капитала среди рассматриваемых компаний. ASML, в свою очередь, демонстрирует высокие значения по всем четырём метрикам, занимая второе место по совокупности показателей и опережая Microsoft по ROE и ROIC. Кроме того, компания сохраняет высокий уровень рентабельности продаж (26,79%), что подтверждает её способность эффективно конвертировать выручку в прибыль. | H40: По итогам анализа показателей рентабельности в группе компаний технологического и полупроводникового сектора для дальнейшего рассмотрения были отобраны Apple (AAPL) и ASML Holding (ASML). Apple занимает первое место по показателям ROE (157,41%), ROA (26,13%) и ROIC (57,18%) в 2024 году, что говорит о наиболее высокой эффективности использования собственного капитала, активов и инвестированного капитала среди рассматриваемых компаний. ASML, в свою очередь, демонстрирует высокие значения по всем четырём метрикам, занимая второе место по совокупности показателей и опережая Microsoft по ROE и ROIC. Кроме того, компания сохраняет высокий уровень рентабельности продаж (26,79%), что подтверждает её способность эффективно конвертировать выручку в прибыль. | P40: По итогам анализа показателей рентабельности в данном блоке выбраны Alphabet/Google (GOOGL) и Meta (META). Alphabet лидирует по ROA (23.48%) и ROIC (29.87%) в 2024 году, что свидетельствует об эффективном использовании активов и инвестированного капитала. Meta показывает наибольшую Profit Margin в отрасли (37.91%) и высокий ROE (37.14%), демонстрируя выдающуюся способность генерировать прибыль. Обе компании показывают устойчивую положительную динамику по всем четырём метрикам на протяжении 2022–2024 годов. Netflix занимает среднюю позицию без явного лидерства ни по одному показателю. T-Mobile и Charter выбывают ввиду низкой рентабельности по всем метрикам и высоккой долговой нагрузки, при этом высокий ROE Charter носит технический характер и объясняется долговой нагрузкой, а не реальной эффективностью бизнеса. | X40: По итогам анализа показателей рентабельности в отрасли здравоохранения, биотехнологий и медицинских технологий были отобраны Regeneron Pharmaceuticals (REGN) и Amgen (AMGN). REGN занимает первое место по показателям ROA (12,46%) и показывает наиболее высокую рентабельность продаж в отрасли (31,07% в 2024 году) при стабильном уровне ROE и ROIC (15,95% и 14,24% соответсственно) на протяжении всего анализируемого периода 2022 - 2024 годов. Подобная ситуация указывает об устойчивой способности данной компании конвертировать выручку в прибыль, не влезая при этом в долги. AMGN, в свою же очередь, лидирует по показателю ROE (67,55% в 2024 году), что обусловено сочетанием высокой операционной эффективности и умеренного долга, характерного для крупных биофармацевтических компаний с диверсифицированным портфелем препаратов. Несмотря на снижение рентабельности по многим метрикам в 2022 году, AMGN сохраняет хороший ROIC и уверенную маржу на уровне 12,24%. | AF40: По итогам анализа показателей рентабельности в группе компаний сектора потребительских товаров повседневного спроса были выбраны Costco Wholesale Corporation (COST) и Pepsico, Inc. (PEP). PepsiCo занимает первое место по показателю ROE на протяжении всего рассматриваемого периода (52.42% в 2024 году), что почти вдвое выше ближайшего конкурента (COST). Высокий ROE при двузначной чистой марже (~10%) указывает на то, что Pepsico зарабатывает на операционной эффективности, а не наращивает показатель за счёт долговой нагрузки. ROA (~9.6%) и ROIC (~17%) остаются стабильно высокими на протяжении всех трёх лет, что подтверждает устойчивость бизнес-модели и способность Pepsico последовательно генерировать прибыль на вложенный капитал. Costco, несмотря на минимальную чистую маржу в группе (2.90% в 2024 году), фиксирует наивысшие значения ROA (10.61%) и ROIC (25.48%) и уступает PepsiCo только по ROE. Компания Costco намеренно держит минимальную торговую наценку, получая основную прибыль за счёт членских взносов покупателей, поэтому при скромной марже Costco показывает выдающуюся отдачу на активы и вложенный капитал (высокая оборачиваемость товаров компенсирует низкую рентабельность каждой продажи).
A41: AAPL | H41: PDD | P41: GOOGL | X41: AMGN | AF41: COST
A42: ASML | H42: MELI | P42: META | X42: REGN | AF42: PEP

Sheet Мультипликаторы
A2: Отрасль 1. Технологии и полупроводники. | H2: Отрасль 2. Потребительский discretionary, e-commerce и онлайн-сервисы. | P2: Отрасль 3. Коммуникационные сервисы, digital-реклама и подписки. | X2: Отрасль 4. Здравоохранение, биотехнологии и медицинские технологии. | AF2: Отрасль 5. Потребительские товары повседневного спроса.
A5: 1 | B5: P/E | H5: 1 | I5: P/E | P5: 1 | Q5: P/E | X5: 1 | Y5: P/E | AF5: 1 | AG5: P/E
B6: Тикер | C6: 2024 | D6: 2023 | E6: 2022 | I6: Тикер | J6: 2024 | K6: 2023 | L6: 2022 | Q6: Тикер | R6: 2024 | S6: 2023 | T6: 2022 | Y6: Тикер | Z6: 2024 | AA6: 2023 | AB6: 2022 | AG6: Тикер | AH6: 2024 | AI6: 2023 | AJ6: 2022
A7: 1 | B7: AAPL | C7: ='P E'!D2 -> 40.926022 | D7: ='P E'!C2 -> 31.056296 | E7: ='P E'!B2 -> 20.910247 | H7: 1 | I7: AMZN | J7: ='P E'!D5 -> 39.672694 | K7: ='P E'!C5 -> 52.393104 | L7: ='P E'!B5 -> -311.11111 | P7: 1 | Q7: GOOGL | R7: ='P E'!D11 -> 23.436426 | S7: ='P E'!C11 -> 23.887058 | T7: ='P E'!B11 -> 19.190079 | X7: 1 | Y7: AMGN | Z7: ='P E'!D4 -> 32.911062 | AA7: ='P E'!C4 -> 21.367546 | AB7: ='P E'!B4 -> 19.422877 | AF7: 1 | AG7: COST | AH7: ='P E'!D9 -> 54.888352 | AI7: ='P E'!C9 -> 45.97496 | AJ7: ='P E'!B9 -> 33.250009
A8: 2 | B8: MSFT | C8: ='P E'!D16 -> 35.301558 | D8: ='P E'!C16 -> 38.106717 | E8: ='P E'!B16 -> 24.163899 | H8: 2 | I8: MELI | J8: ='P E'!D14 -> 45.116475 | K8: ='P E'!C14 -> 80.757453 | L8: ='P E'!B14 -> 88.797481 | P8: 2 | Q8: META | R8: ='P E'!D15 -> 24.441331 | S8: ='P E'!C15 -> 23.618286 | T8: ='P E'!B15 -> 13.900232 | X8: 2 | Y8: REGN | Z8: ='P E'!D20 -> 18.427095 | AA8: ='P E'!C20 -> 25.053071 | AB8: ='P E'!B20 -> 18.722652 | AF8: 2 | AG8: PEP | AH8: ='P E'!D19 -> 20.852117 | AI8: ='P E'!C19 -> 23.90929 | AJ8: ='P E'!B19 -> 25.261886
A9: 3 | B9: ASML | C9: ='P E'!D6 -> 35.557236 | D9: ='P E'!C6 -> 35.997379 | E9: ='P E'!B6 -> 32.967321 | H9: 3 | I9: TSLA | J9: ='P E'!D22 -> 197.96078 | K9: ='P E'!C22 -> 57.651971 | L9: ='P E'!B22 -> 34.027624 | P9: 3 | Q9: NFLX | R9: ='P E'!D17 -> 44.94806 | S9: ='P E'!C17 -> 40.472153 | T9: ='P E'!B17 -> 29.636182 | X9: 3 | Y9: GILD | Z9: ='P E'!D10 -> 235.1328 | AA9: ='P E'!C10 -> 16.730058 | AB9: ='P E'!B10 -> 21.10331 | AF9: 3 | AG9: MDLZ | AH9: ='P E'!D13 -> 16.784746 | AI9: ='P E'!C13 -> 18.721225 | AJ9: ='P E'!B13 -> 31.101937
A10: 4 | B10: AMD | C10: ='P E'!D3 -> 120.79 | D10: ='P E'!C3 -> 278.13208 | E10: ='P E'!B3 -> 77.107139 | H10: 4 | I10: PDD | J10: ='P E'!D18 -> 1.2761842 | K10: ='P E'!C18 -> 3.5546647 | L10: ='P E'!B18 -> 3.7203469 | P10: 4 | Q10: TMUS | R10: ='P E'!D21 -> 22.270373 | S10: ='P E'!C21 -> 22.221057 | T10: ='P E'!B21 -> 64.990849 | X10: 4 | Y10: VRTX | Z10: ='P E'!D23 -> -193.60578 | AA10: ='P E'!C23 -> 29.293738 | AB10: ='P E'!B23 -> 22.525741 | AF10: 4 | AG10: KDP | AH10: ='P E'!D12 -> 29.185956 | AI10: ='P E'!C12 -> 19.981232 | AJ10: ='P E'!B12 -> 32.020773
P11: 5 | Q11: CHTR | R11: ='P E'!D8 -> 9.8018298 | S11: ='P E'!C8 -> 12.96032 | T11: ='P E'!B8 -> 11.03123 | AF11: 5 | AG11: CCEP | AH11: ='P E'!D7 -> 24.040782 | AI11: ='P E'!C7 -> 17.235252 | AJ11: ='P E'!B7 -> 15.274151
A13: 2 | B13: PEG | H13: 2 | I13: PEG | P13: 2 | Q13: PEG | X13: 2 | Y13: PEG | AF13: 2 | AG13: PEG
C14: 2024 | J14: 2024 | R14: 2024 | Z14: 2024 | AH14: 2024
A15: 1 | B15: AAPL | C15: =PEG!B2 -> -16650.045 | H15: 1 | I15: AMZN | J15: =PEG!B5 | P15: 1 | Q15: GOOGL | R15: =PEG!B11 -> 71.487486 | X15: 1 | Y15: AMGN | Z15: =PEG!B4 -> -156.8032 | AF15: 1 | AG15: COST | AH15: =PEG!B9 -> 447.63244
A16: 2 | B16: MSFT | C16: =PEG!B16 -> 333.657 | H16: 2 | I16: MELI | J16: =PEG!B14 -> 45.632679 | P16: 2 | Q16: META | R16: =PEG!B15 -> 36.664131 | X16: 2 | Y16: REGN | Z16: =PEG!B20 -> 11747.266 | AF16: 2 | AG16: PEP | AH16: =PEG!B19 -> 515.39136
A17: 3 | B17: ASML | C17: =PEG!B6 -> 377.4867 | H17: 3 | I17: TSLA | P17: 3 | Q17: NFLX | R17: =PEG!B17 -> 109.17035 | X17: 3 | Y17: GILD | Z17: =PEG!B10 -> -347.3687 | AF17: 3 | AG17: MDLZ | AH17: =PEG!B13 -> 52.297749
A18: 4 | B18: AMD | C18: =PEG!B3 -> 1326.0592 | H18: 4 | I18: PDD | J18: =PEG!B18 -> 1.4804417 | P18: 4 | Q18: TMUS | R18: =PEG!B21 -> 19.108264 | X18: 4 | Y18: VRTX | Z18: =PEG!B23 | AF18: 4 | AG18: KDP | AH18: =PEG!B12 -> 1488.3421
P19: 5 | Q19: CHTR | R19: =PEG!B8 -> 147.20553 | AF19: 5 | AG19: CCEP | AH19: =PEG!B7 -> -741.05925
A21: 3 | B21: P/S | H21: 3 | I21: P/S | P21: 3 | Q21: P/S | X21: 3 | Y21: P/S | AF21: 3 | AG21: P/S
B22: Тикер | C22: 2024 | D22: 2023 | E22: 2022 | I22: Тикер | J22: 2024 | K22: 2023 | L22: 2022 | Q22: Тикер | R22: 2024 | S22: 2023 | T22: 2022 | Y22: Тикер | Z22: 2024 | AA22: 2023 | AB22: 2022 | AG22: Тикер | AH22: 2024 | AI22: 2023 | AJ22: 2022
A23: 1 | B23: AAPL | C23: ='P S'!D2 -> 9.8047479 | D23: ='P S'!C2 -> 7.8539862 | E23: ='P S'!B2 -> 5.289538 | H23: 1 | I23: AMZN | J23: ='P S'!D5 -> 3.686883 | K23: ='P S'!C5 -> 2.7734797 | L23: ='P S'!B5 -> 1.6651835 | P23: 1 | Q23: GOOGL | R23: ='P S'!D11 -> 6.7007241 | S23: ='P S'!C11 -> 5.7339073 | T23: ='P S'!B11 -> 4.071269 | X23: 1 | Y23: AMGN | Z23: ='P S'!D4 -> 4.0271939 | AA23: ='P S'!C4 -> 5.0933589 | AB23: ='P S'!B4 -> 4.8341441 | AF23: 1 | AG23: COST | AH23: ='P S'!D9 -> 1.5887578 | AI23: ='P S'!C9 -> 1.1941915 | AJ23: ='P S'!B9 -> 0.85619381
A24: 2 | B24: MSFT | C24: ='P S'!D16 -> 12.692759 | D24: ='P S'!C16 -> 13.006249 | E24: ='P S'!B16 -> 8.8676525 | H24: 2 | I24: MELI | J24: ='P S'!D14 -> 4.1492001 | K24: ='P S'!C14 -> 5.3060422 | L24: ='P S'!B14 -> 4.0298938 | P24: 2 | Q24: META | R24: ='P S'!D15 -> 9.2668544 | S24: ='P S'!C15 -> 6.8443396 | T24: ='P S'!B15 -> 2.7667409 | X24: 2 | Y24: REGN | Z24: ='P S'!D20 -> 5.7257818 | AA24: ='P S'!C20 -> 7.5506612 | AB24: ='P S'!B20 -> 6.6720588 | AF24: 2 | AG24: PEP | AH24: ='P S'!D19 -> 2.1741329 | AI24: ='P S'!C19 -> 2.3714243 | AJ24: ='P S'!B19 -> 2.6037766
A25: 3 | B25: ASML | C25: ='P S'!D6 -> 9.5273348 | D25: ='P S'!C6 -> 10.599322 | E25: ='P S'!B6 -> 9.9584559 | H25: 3 | I25: TSLA | J25: ='P S'!D22 -> 13.2946 | K25: ='P S'!C22 -> 8.9425119 | L25: ='P S'!B22 -> 5.2546034 | P25: 3 | Q25: NFLX | R25: ='P S'!D17 -> 10.03878 | S25: ='P S'!C17 -> 6.489626 | T25: ='P S'!B17 -> 4.2092072 | X25: 3 | Y25: GILD | Z25: ='P S'!D10 -> 3.8997994 | AA25: ='P S'!C10 -> 3.4927298 | AB25: ='P S'!B10 -> 3.5534567 | AF25: 3 | AG25: MDLZ | AH25: ='P S'!D13 -> 2.1218672 | AI25: ='P S'!C13 -> 2.5779111 | AJ25: ='P S'!B13 -> 2.6806362
A26: 4 | B26: AMD | C26: ='P S'!D3 -> 7.6685372 | D26: ='P S'!C3 -> 10.561784 | E26: ='P S'!B3 -> 4.3114133 | H26: 4 | I26: PDD | J26: ='P S'!D18 -> 0.36426971 | K26: ='P S'!C18 -> 0.86254138 | L26: ='P S'!B18 -> 0.89966677 | P26: 4 | Q26: TMUS | R26: ='P S'!D21 -> 3.1006833 | S26: ='P S'!C21 -> 2.3528399 | T26: ='P S'!B21 -> 2.1122178 | X26: 4 | Y26: VRTX | Z26: ='P S'!D23 -> 9.4242641 | AA26: ='P S'!C23 -> 10.739964 | AB26: ='P S'!B23 -> 8.3781672 | AF26: 4 | AG26: KDP | AH26: ='P S'!D12 -> 2.731542 | AI26: ='P S'!C12 -> 2.9444734 | AJ26: ='P S'!B12 -> 3.2865541
P27: 5 | Q27: CHTR | R27: ='P S'!D8 -> 0.9045355 | S27: ='P S'!C8 -> 1.0816611 | T27: ='P S'!B8 -> 1.0321616 | AF27: 5 | AG27: CCEP | AH27: ='P S'!D7 -> 1.6701745 | AI27: ='P S'!C7 -> 1.5717209 | AJ27: ='P S'!B7 -> 1.3298741
A29: 4 | B29: EV/EBITDA | H29: 4 | I29: EV/EBITDA | X29: 4 | Y29: EV/EBITDA
B30: Тикер | C30: 2024 | D30: 2023 | E30: 2022 | I30: Тикер | J30: 2024 | K30: 2023 | L30: 2022 | P30: 4 | Q30: EV/EBITDA | Y30: Тикер | Z30: 2024 | AA30: 2023 | AB30: 2022 | AF30: 4 | AG30: EV/EBITDA
A31: 1 | B31: AAPL | C31: ='EV EBITDA'!D2 -> 29.040967 | D31: ='EV EBITDA'!C2 -> 24.570323 | E31: ='EV EBITDA'!B2 -> 16.811936 | H31: 1 | I31: AMZN | J31: ='EV EBITDA'!D5 -> 19.417689 | K31: ='EV EBITDA'!C5 -> 18.527309 | L31: ='EV EBITDA'!B5 -> 24.564716 | Q31: Тикер | R31: 2024 | S31: 2023 | T31: 2022 | X31: 1 | Y31: AMGN | Z31: ='EV EBITDA'!D4 -> 13.681561 | AA31: ='EV EBITDA'!C4 -> 13.326855 | AB31: ='EV EBITDA'!B4 -> 13.030255 | AG31: Тикер | AH31: 2024 | AI31: 2023 | AJ31: 2022
A32: 2 | B32: MSFT | C32: ='EV EBITDA'!D16 -> 23.758441 | D32: ='EV EBITDA'!C16 -> 26.455014 | E32: ='EV EBITDA'!B16 -> 18.012235 | H32: 2 | I32: MELI | J32: ='EV EBITDA'!D14 -> 28.134079 | K32: ='EV EBITDA'!C14 -> 36.843794 | L32: ='EV EBITDA'!B14 -> 35.619314 | P32: 1 | Q32: GOOGL | R32: ='EV EBITDA'!D11 -> 17.315997 | S32: ='EV EBITDA'!C11 -> 18.022085 | T32: ='EV EBITDA'!B11 -> 13.613216 | X32: 2 | Y32: REGN | Z32: ='EV EBITDA'!D20 -> 15.331657 | AA32: ='EV EBITDA'!C20 -> 21.097401 | AB32: ='EV EBITDA'!B20 -> 15.36501 | AF32: 1 | AG32: COST | AH32: ='EV EBITDA'!D9 -> 33.14072 | AI32: ='EV EBITDA'!C9 -> 26.53158 | AJ32: ='EV EBITDA'!B9 -> 19.514307
A33: 3 | B33: ASML | C33: ='EV EBITDA'!D6 -> 25.803253 | D33: ='EV EBITDA'!C6 -> 29.042534 | E33: ='EV EBITDA'!B6 -> 29.272089 | H33: 3 | I33: TSLA | J33: ='EV EBITDA'!D22 -> 88.131182 | K33: ='EV EBITDA'!C22 -> 58.027082 | L33: ='EV EBITDA'!B22 -> 23.64759 | P33: 2 | Q33: META | R33: ='EV EBITDA'!D15 -> 17.606448 | S33: ='EV EBITDA'!C15 -> 15.557256 | T33: ='EV EBITDA'!B15 -> 8.8760118 | X33: 3 | Y33: GILD | Z33: ='EV EBITDA'!D10 -> 29.06063 | AA33: ='EV EBITDA'!C10 -> 10.824205 | AB33: ='EV EBITDA'!B10 -> 13.190223 | AF33: 2 | AG33: PEP | AH33: ='EV EBITDA'!D19 -> 14.157422 | AI33: ='EV EBITDA'!C19 -> 15.987467 | AJ33: ='EV EBITDA'!B19 -> 17.391146
A34: 4 | B34: AMD | C34: ='EV EBITDA'!D3 -> 38.125993 | D34: ='EV EBITDA'!C3 -> 58.901816 | E34: ='EV EBITDA'!B3 -> 18.030659 | H34: 4 | I34: PDD | J34: ='EV EBITDA'!D18 -> 0.71163259 | K34: ='EV EBITDA'!C18 -> 2.2214207 | L34: ='EV EBITDA'!B18 -> 2.5523411 | P34: 3 | Q34: NFLX | R34: ='EV EBITDA'!D17 -> 15.173966 | S34: ='EV EBITDA'!C17 -> 10.520451 | T34: ='EV EBITDA'!B17 -> 6.9976203 | X34: 4 | Y34: VRTX | Z34: ='EV EBITDA'!D23 -> 207.75454 | AA34: ='EV EBITDA'!C23 -> 20.940274 | AB34: ='EV EBITDA'!B23 -> 14.703776 | AF34: 3 | AG34: MDLZ | AH34: ='EV EBITDA'!D13 -> 11.689253 | AI34: ='EV EBITDA'!C13 -> 14.516814 | AJ34: ='EV EBITDA'!B13 -> 22.245081
P35: 4 | Q35: TMUS | R35: ='EV EBITDA'!D21 -> 11.62717 | S35: ='EV EBITDA'!C21 -> 10.783198 | T35: ='EV EBITDA'!B21 -> 13.657868 | AF35: 4 | AG35: KDP | AH35: ='EV EBITDA'!D12 -> 16.846807 | AI35: ='EV EBITDA'!C12 -> 14.642947 | AJ35: ='EV EBITDA'!B12 -> 18.983368
H36: Выводы (мультипликаторы): | P36: 5 | Q36: CHTR | R36: ='EV EBITDA'!D8 -> 6.7805241 | S36: ='EV EBITDA'!C8 -> 7.5493908 | T36: ='EV EBITDA'!B8 -> 7.2997196 | X36: Выводы (мультипликаторы): | AF36: 5 | AG36: CCEP | AH36: ='EV EBITDA'!D7 -> 14.112191 | AI36: ='EV EBITDA'!C7 -> 12.271978 | AJ36: ='EV EBITDA'!B7 -> 11.43217
A37: Выводы (мультипликаторы):
A38: По мультипликаторам за 2022-2024 годы в выборку вошли Apple и ASML. Apple лидировала по P/E и EV/EBITDA в 2022-2023 годах, и даже с переходом на третьи места в 2024 году остается привлекательной по совокупности периода. ASML - самая стабильная в блоке, без резких колебаний удерживает вторые и третьи позиции по всем коэффициентам. Microsoft показала лучшие P/E и EV/EBITDA в 2024 году, но все три года проигрывает остальным по соотношению цены и выручки (P/S). AMD выбывает из-за критически высоких, худших в группе значений P/E и EV/EBITDA, несмотря на лидерство по оценке выручки (P/S). | P38: Выводы (мультипликаторы): | AF38: Выводы (мультипликаторы):
H40: По итогам анализа мультипликаторов лидерами по привлекательности рыночной оценки в данном блоке являются PDD Holdings (PDD) и Amazon (AMZN). PDD демонстрирует наименьшие значения P/E (1.28), P/S (0.36) и EV/EBITDA (0.71) в 2024 году - значительно ниже, чем у любого другого конкурента в отрасли; PEG (1.48) указывает на разумную оценку с учётом темпов роста. Столь низкие мультипликаторы при сильных фундаментальных показателях отчасти объясняются специфическим дисконтом за геополитический и регуляторный риск, характерным для китайских компаний на NASDAQ, однако не отражают слабости бизнеса. Amazon занимает второе место по совокупности мультипликаторов (P/E=39.67, P/S=3.69, EV/EBITDA=19.42 в 2024 году), что является адекватной оценкой для крупнейшего e-commerce-оператора с быстрорастущим облачным сегментом (AWS). MercadoLibre торгуется с заметной премией к Amazon (P/E=45.12, EV/EBITDA=28.13), что оправдывается высокими темпами роста, однако ограничивает запас прочности оценки. Tesla имеет наиболее высокие мультипликаторы в отрасли (P/E=197.96, P/S=13.29, EV/EBITDA=88.13) - оценка существенно расходится с текущим уровнем рентабельности и делает акцию крайне чувствительной к разочаровывающим операционным результатам. | P40: По итогам анализа мультипликаторов формальными лидерами по дешевизне оценки в данном блоке являются Charter Communications (CHTR) и T-Mobile (TMUS). CHTR демонстрирует наименьший P/E (9.80) и EV/EBITDA (6.78) в 2024 году, TMUS показывает низкий P/S (3.10) и умеренный P/E (22.27). Однако низкая оценка требует контекста: в случае CHTR она обусловлена критически высокой долговой нагрузкой и слабой операционной эффективностью, в случае TMUS - зрелостью телеком-бизнеса с ограниченным потенциалом роста. Alphabet/Google и Meta торгуются с более высокими мультипликаторами, что отражает справедливую премию за доминирующие позиции в digital-рекламе и стабильно высокую рентабельность. Netflix имеет наиболее высокий P/E (44.95) и P/S (10.04) в отрасли, что делает акцию наиболее чувствительной к негативным изменениям в результатах компании. | X40: По итогам анализа мультипликаторов в группе компаний сектора здравоохранения, биотехнологий и медицинских технологий наиболее привлекательную рыночную оценку демонстрируют Regeneron Pharmaceuticals (REGN) и Amgen (AMGN). REGN показывает наиболее разумные мультипликаторы в отрасли: P/E = 18,43, EV/EBITDA = 15,33 и P/S = 5,73 в 2024 году при PEG = 11 747, что объясняется временным замедлением темпов роста прибыли. Уровень P/E у REGN является наиболее низким среди компаний с положительной рентабельностью в группе и подтверждает сдержанную рыночную оценку с учетом сильных фундаментальных показателей. AMGN также торгуется с умеренными мультипликаторами: P/E = 32,91, а EV/EBITDA = 13,68 является наименьшим значение EV/EBITDA в группе за 2024 год, что указывает на наиболее привлекательную оценку по операционному денежному потоку. Показатель PEG у AMGN является отрицательным, что связано со снижением прибыли в отчетном периоде на фоне интеграционных расходов. GILD не был выбран из-за его чересчур высокого показателя P/E (235x) в 2024 году, вызванного разовым сжатием чистой прибыли (также у него высокий EV/EBITDA). VRTX также не был учтен из-за его отрицательных показателей рентабельности, что делает P/E нерасчетным, а EV/EBITDA достигает критических выоских значений (207,75x). | AF40: По итогам анализа мультипликаторов в группе компаний сектора потребительских товаров повседневного спроса были отобраны Mondelez International, Inc. (MDLZ) и Coca-Cola Europacific Partners (CCEP). Mondelez демонстрирует одни из наиболее низких значений P/E (16.78) и EV/EBITDA (11.69) в группе по итогам 2024 года. Показатель EV/EBITDA снизился с 22.25 в 2022 году до 11.69 в 2024 году при сохранении стабильных операционных результатов, что указывает на возможную недооцененность акций компании. Coca-Cola Europacific Partners выделяется достаточно низким значением P/S (1.67) и конкурентным уровнем EV/EBITDA (14.11) в 2024 году. В секторе с относительно устойчивым уровнем рентабельности низкий P/S при устойчивой выручке свидетельствует о сдержанной рыночной оценке компании. Последовательное улучшение мультипликаторов на протяжении всего анализируемого периода отражает рост доверия рынка к бизнес-модели компании. Costco исключается из-за переоценённости (P/E = 55, EV/EBITDA = 33), PepsiCo не выбираем из-за отсутствия лидирующих позиций по мультипликаторам, а KDP из-за высокой оценки при низкой рентабельности.
H41: PDD | P41: CHTR | X41: REGN | AF41: CCEP
H42: AMZN | P42: TMUS | X42: AMGN | AF42: MDLZ
A45: AAPL
A46: ASML

Sheet Показатели фин устойчивости
A2: Отрасль 1. Технологии и полупроводники. | H2: Отрасль 2. Потребительский discretionary, e-commerce и онлайн-сервисы. | P2: Отрасль 3. Коммуникационные сервисы, digital-реклама и подписки. | X2: Отрасль 4. Здравоохранение, биотехнологии и медицинские технологии. | AF2: Отрасль 5. Потребительские товары повседневного спроса.
A5: 1 | B5: ND/EBITDA | H5: 1 | I5: ND/EBITDA | P5: 1 | Q5: ND/EBITDA | X5: 1 | Y5: ND/EBITDA | AF5: 1 | AG5: ND/EBITDA
B6: Тикер | C6: 2024 | D6: 2023 | E6: 2022 | I6: Тикер | J6: 2024 | K6: 2023 | L6: 2022 | Q6: Тикер | R6: 2024 | S6: 2023 | T6: 2022 | Y6: Тикер | Z6: 2024 | AA6: 2023 | AB6: 2022 | AG6: Тикер | AH6: 2024 | AI6: 2023 | AJ6: 2022
A7: 1 | B7: AAPL | C7: ='Net Debt EBITDA'!D2 -> 0.56947446 | D7: ='Net Debt EBITDA'!C2 -> 0.64475441 | E7: ='Net Debt EBITDA'!B2 -> 0.83371508 | H7: 1 | I7: AMZN | J7: ='Net Debt EBITDA'!D5 -> 0.42095869 | K7: ='Net Debt EBITDA'!C5 -> 0.69600233 | L7: ='Net Debt EBITDA'!B5 -> 2.2483834 | P7: 1 | Q7: GOOGL | R7: ='Net Debt EBITDA'!D11 -> -0.0065881797 | S7: ='Net Debt EBITDA'!C11 -> 0.031366425 | T7: ='Net Debt EBITDA'!B11 -> 0.091592297 | X7: 1 | Y7: AMGN | Z7: ='Net Debt EBITDA'!D4 -> 3.6033243 | AA7: ='Net Debt EBITDA'!C4 -> 3.6260388 | AB7: ='Net Debt EBITDA'!B4 -> 2.5734243 | AF7: 1 | AG7: COST | AH7: ='Net Debt EBITDA'!D9 -> -0.14301004 | AI7: ='Net Debt EBITDA'!C9 -> -0.44908616 | AJ7: ='Net Debt EBITDA'!B9 -> -0.11759952
A8: 2 | B8: MSFT | C8: ='Net Debt EBITDA'!D16 -> 0.36698269 | D8: ='Net Debt EBITDA'!C16 -> 0.2402606 | E8: ='Net Debt EBITDA'!B16 -> 0.4722613 | H8: 2 | I8: MELI | J8: ='Net Debt EBITDA'!D14 -> 1.3114499 | K8: ='Net Debt EBITDA'!C14 -> 1.2336739 | L8: ='Net Debt EBITDA'!B14 -> 2.6585736 | P8: 2 | Q8: META | R8: ='Net Debt EBITDA'!D15 -> 0.059521617 | S8: ='Net Debt EBITDA'!C15 -> -0.078371605 | T8: ='Net Debt EBITDA'!B15 -> 0.31599894 | X8: 2 | Y8: REGN | Z8: ='Net Debt EBITDA'!D20 -> 0.040654381 | AA8: ='Net Debt EBITDA'!C20 -> -0.0057741887 | AB8: ='Net Debt EBITDA'!B20 -> -0.076906989 | AF8: 2 | AG8: PEP | AH8: ='Net Debt EBITDA'!D19 -> 2.1848321 | AI8: ='Net Debt EBITDA'!C19 -> 2.2184842 | AJ8: ='Net Debt EBITDA'!B19 -> 2.3184133
A9: 3 | B9: ASML | C9: ='Net Debt EBITDA'!D6 -> -0.79500375 | D9: ='Net Debt EBITDA'!C6 -> -0.23788091 | E9: ='Net Debt EBITDA'!B6 -> -0.42361806 | H9: 3 | I9: TSLA | J9: ='Net Debt EBITDA'!D22 -> -0.17106337 | K9: ='Net Debt EBITDA'!C22 -> -0.46127332 | L9: ='Net Debt EBITDA'!B22 -> -0.59494818 | P9: 3 | Q9: NFLX | R9: ='Net Debt EBITDA'!D17 -> 0.29557758 | S9: ='Net Debt EBITDA'!C17 -> 0.34527684 | T9: ='Net Debt EBITDA'!B17 -> 0.4527576 | X9: 3 | Y9: GILD | Z9: ='Net Debt EBITDA'!D10 -> 3.7708615 | AA9: ='Net Debt EBITDA'!C10 -> 1.8008765 | AB9: ='Net Debt EBITDA'!B10 -> 2.2388161 | AF9: 3 | AG9: MDLZ | AH9: ='Net Debt EBITDA'!D13 -> 2.1089084 | AI9: ='Net Debt EBITDA'!C13 -> 2.3721387 | AJ9: ='Net Debt EBITDA'!B13 -> 4.5190006
A10: 4 | B10: AMD | C10: ='Net Debt EBITDA'!D3 -> -0.30612245 | D10: ='Net Debt EBITDA'!C3 -> -0.22957295 | E10: ='Net Debt EBITDA'!B3 -> -0.35634261 | H10: 4 | I10: PDD | J10: ='Net Debt EBITDA'!D18 -> -0.34850123 | K10: ='Net Debt EBITDA'!C18 -> -0.67235222 | L10: ='Net Debt EBITDA'!B18 -> -0.443605 | P10: 4 | Q10: TMUS | R10: ='Net Debt EBITDA'!D21 -> 3.496392 | S10: ='Net Debt EBITDA'!C21 -> 3.9758029 | T10: ='Net Debt EBITDA'!B21 -> 5.3214126 | X10: 4 | Y10: VRTX | Z10: ='Net Debt EBITDA'!D23 -> -5.8097882 | AA10: ='Net Debt EBITDA'!C23 -> -2.0760662 | AB10: ='Net Debt EBITDA'!B23 -> -2.1653252 | AF10: 4 | AG10: KDP | AH10: ='Net Debt EBITDA'!D12 -> 4.4482555 | AI10: ='Net Debt EBITDA'!C12 -> 3.6639819 | AJ10: ='Net Debt EBITDA'!B12 -> 4.1807113
P11: 5 | Q11: CHTR | R11: ='Net Debt EBITDA'!D8 -> 4.4526257 | S11: ='Net Debt EBITDA'!C8 -> 4.7011766 | T11: ='Net Debt EBITDA'!B8 -> 4.6344821 | AF11: 5 | AG11: CCEP | AH11: ='Net Debt EBITDA'!D7 -> 3.1398264 | AI11: ='Net Debt EBITDA'!C7 -> 3.1602787 | AJ11: ='Net Debt EBITDA'!B7 -> 3.5843271
A13: 2 | B13: Current Ratio | H13: 2 | I13: Current Ratio | X13: 2 | Y13: Current Ratio
B14: Тикер | C14: 2024 | D14: 2023 | E14: 2022 | I14: Тикер | J14: 2024 | K14: 2023 | L14: 2022 | P14: 2 | Q14: Current Ratio | Y14: Тикер | Z14: 2024 | AA14: 2023 | AB14: 2022 | AF14: 2 | AG14: Current Ratio
A15: 1 | B15: AAPL | C15: ='Current Ratio'!D2 -> 0.86731258 | D15: ='Current Ratio'!C2 -> 0.98801167 | E15: ='Current Ratio'!B2 -> 0.87935603 | H15: 1 | I15: AMZN | J15: ='Current Ratio'!D5 -> 1.0637348 | K15: ='Current Ratio'!C5 -> 1.0450772 | L15: ='Current Ratio'!B5 -> 0.94464358 | Q15: Тикер | R15: 2024 | S15: 2023 | T15: 2022 | X15: 1 | Y15: AMGN | Z15: ='Current Ratio'!D4 -> 1.2567644 | AA15: ='Current Ratio'!C4 -> 1.6491953 | AB15: ='Current Ratio'!B4 -> 1.4142921 | AG15: Тикер | AH15: 2024 | AI15: 2023 | AJ15: 2022
A16: 2 | B16: MSFT | C16: ='Current Ratio'!D16 -> 1.2749549 | D16: ='Current Ratio'!C16 -> 1.7691673 | E16: ='Current Ratio'!B16 -> 1.784607 | H16: 2 | I16: MELI | J16: ='Current Ratio'!D14 -> 1.2131542 | K16: ='Current Ratio'!C14 -> 1.2660925 | L16: ='Current Ratio'!B14 -> 1.2792572 | P16: 1 | Q16: GOOGL | R16: ='Current Ratio'!D11 -> 1.8369314 | S16: ='Current Ratio'!C11 -> 2.0965849 | T16: ='Current Ratio'!B11 -> 2.3779942 | X16: 2 | Y16: REGN | Z16: ='Current Ratio'!D20 -> 4.7311056 | AA16: ='Current Ratio'!C20 -> 5.6900158 | AB16: ='Current Ratio'!B20 -> 5.0565371 | AF16: 1 | AG16: COST | AH16: ='Current Ratio'!D9 -> 0.96565531 | AI16: ='Current Ratio'!C9 -> 1.0683679 | AJ16: ='Current Ratio'!B9 -> 1.0218139
A17: 3 | B17: ASML | C17: ='Current Ratio'!D6 -> 1.5329304 | D17: ='Current Ratio'!C6 -> 1.4988848 | E17: ='Current Ratio'!B6 -> 1.2825519 | H17: 3 | I17: TSLA | J17: ='Current Ratio'!D22 -> 2.0249124 | K17: ='Current Ratio'!C22 -> 1.725894 | L17: ='Current Ratio'!B22 -> 1.5319555 | P17: 2 | Q17: META | R17: ='Current Ratio'!D15 -> 2.9778843 | S17: ='Current Ratio'!C15 -> 2.670995 | T17: ='Current Ratio'!B15 -> 2.2033967 | X17: 3 | Y17: GILD | Z17: ='Current Ratio'!D10 -> 1.5972176 | AA17: ='Current Ratio'!C10 -> 1.4259752 | AB17: ='Current Ratio'!B10 -> 1.2851931 | AF17: 2 | AG17: PEP | AH17: ='Current Ratio'!D19 -> 0.81893709 | AI17: ='Current Ratio'!C19 -> 0.85158151 | AJ17: ='Current Ratio'!B19 -> 0.80414411
A18: 4 | B18: AMD | C18: ='Current Ratio'!D3 -> 2.6162615 | D18: ='Current Ratio'!C3 -> 2.5068022 | E18: ='Current Ratio'!B3 -> 2.358141 | H18: 4 | I18: PDD | J18: ='Current Ratio'!D18 -> 2.2059332 | K18: ='Current Ratio'!C18 -> 1.9277223 | L18: ='Current Ratio'!B18 -> 1.8531854 | P18: 3 | Q18: NFLX | R18: ='Current Ratio'!D17 -> 1.2180281 | S18: ='Current Ratio'!C17 -> 1.1193454 | T18: ='Current Ratio'!B17 -> 1.1683903 | X18: 4 | Y18: VRTX | Z18: ='Current Ratio'!D23 -> 2.6921394 | AA18: ='Current Ratio'!C23 -> 3.9872019 | AB18: ='Current Ratio'!B23 -> 4.8265198 | AF18: 3 | AG18: MDLZ | AH18: ='Current Ratio'!D13 -> 0.6773748 | AI18: ='Current Ratio'!C13 -> 0.61552622 | AJ18: ='Current Ratio'!B13 -> 0.60313191
P19: 4 | Q19: TMUS | R19: ='Current Ratio'!D21 -> 0.91226331 | S19: ='Current Ratio'!C21 -> 0.90859136 | T19: ='Current Ratio'!B21 -> 0.77063293 | AF19: 4 | AG19: KDP | AH19: ='Current Ratio'!D12 -> 0.49425003 | AI19: ='Current Ratio'!C12 -> 0.37853297 | AJ19: ='Current Ratio'!B12 -> 0.47102526
P20: 5 | Q20: CHTR | R20: ='Current Ratio'!D8 -> 0.31388106 | S20: ='Current Ratio'!C8 -> 0.31269865 | T20: ='Current Ratio'!B8 -> 0.33294654 | AF20: 5 | AG20: CCEP | AH20: ='Current Ratio'!D7 -> 0.81457848 | AI20: ='Current Ratio'!C7 -> 0.90752954 | AJ20: ='Current Ratio'!B7 -> 0.89470805
A21: 3 | B21: Quick Ratio | H21: 3 | I21: Quick Ratio | X21: 3 | Y21: Quick Ratio
B22: Тикер | C22: 2024 | D22: 2023 | E22: 2022 | I22: Тикер | J22: 2024 | K22: 2023 | L22: 2022 | Y22: Тикер | Z22: 2024 | AA22: 2023 | AB22: 2022
A23: 1 | B23: AAPL | C23: ='Quick Ratio'!D2 -> 0.82600685 | D23: ='Quick Ratio'!C2 -> 0.94444215 | E23: ='Quick Ratio'!B2 -> 0.84723539 | H23: 1 | I23: AMZN | J23: ='Quick Ratio'!D5 -> 0.87305427 | K23: ='Quick Ratio'!C5 -> 0.84304832 | L23: ='Quick Ratio'!B5 -> 0.72323721 | P23: 3 | Q23: Quick Ratio | X23: 1 | Y23: AMGN | Z23: ='Quick Ratio'!D4 -> 0.95380752 | AA23: ='Quick Ratio'!C4 -> 1.1316877 | AB23: ='Quick Ratio'!B4 -> 1.1000191 | AF23: 3 | AG23: Quick Ratio
A24: 2 | B24: MSFT | C24: ='Quick Ratio'!D16 -> 1.2650097 | D24: ='Quick Ratio'!C16 -> 1.7451632 | E24: ='Quick Ratio'!B16 -> 1.7452515 | H24: 2 | I24: MELI | J24: ='Quick Ratio'!D14 -> 1.1953261 | K24: ='Quick Ratio'!C14 -> 1.2449614 | L24: ='Quick Ratio'!B14 -> 1.2615043 | Q24: Тикер | R24: 2024 | S24: 2023 | T24: 2022 | X24: 2 | Y24: REGN | Z24: ='Quick Ratio'!D20 -> 3.9483812 | AA24: ='Quick Ratio'!C20 -> 4.936233 | AB24: ='Quick Ratio'!B20 -> 4.2919174 | AG24: Тикер | AH24: 2024 | AI24: 2023 | AJ24: 2022
A25: 3 | B25: ASML | C25: ='Quick Ratio'!D6 -> 0.98975134 | D25: ='Quick Ratio'!C6 -> 0.95505293 | E25: ='Quick Ratio'!B6 -> 0.88220379 | H25: 3 | I25: TSLA | J25: ='Quick Ratio'!D22 -> 1.6079595 | K25: ='Quick Ratio'!C22 -> 1.2519132 | L25: ='Quick Ratio'!B22 -> 1.0512561 | P25: 1 | Q25: GOOGL | R25: ='Quick Ratio'!D11 -> 1.8069725 | S25: ='Quick Ratio'!C11 -> 2.0639499 | T25: ='Quick Ratio'!B11 -> 2.3394661 | X25: 3 | Y25: GILD | Z25: ='Quick Ratio'!D10 -> 1.4547651 | AA25: ='Quick Ratio'!C10 -> 1.2675532 | AB25: ='Quick Ratio'!B10 -> 1.1510945 | AF25: 1 | AG25: COST | AH25: ='Quick Ratio'!D9 -> 0.4398545 | AI25: ='Quick Ratio'!C9 -> 0.57255159 | AJ25: ='Quick Ratio'!B9 -> 0.46218514
A26: 4 | B26: AMD | C26: ='Quick Ratio'!D3 -> 1.8287323 | D26: ='Quick Ratio'!C3 -> 1.8563313 | E26: ='Quick Ratio'!B3 -> 1.7660543 | H26: 4 | I26: PDD | J26: ='Quick Ratio'!D18 -> 2.2059332 | K26: ='Quick Ratio'!C18 -> 1.9277223 | L26: ='Quick Ratio'!B18 -> 1.8531854 | P26: 2 | Q26: META | R26: ='Quick Ratio'!D15 -> 2.9778843 | S26: ='Quick Ratio'!C15 -> 2.670995 | T26: ='Quick Ratio'!B15 -> 2.2033967 | X26: 4 | Y26: VRTX | Z26: ='Quick Ratio'!D23 -> 2.3539808 | AA26: ='Quick Ratio'!C23 -> 3.7789367 | AB26: ='Quick Ratio'!B23 -> 4.6585464 | AF26: 2 | AG26: PEP | AH26: ='Quick Ratio'!D19 -> 0.65068493 | AI26: ='Quick Ratio'!C19 -> 0.68303473 | AJ26: ='Quick Ratio'!B19 -> 0.60918424
P27: 3 | Q27: NFLX | R27: ='Quick Ratio'!D17 -> 1.2180281 | S27: ='Quick Ratio'!C17 -> 1.1193454 | T27: ='Quick Ratio'!B17 -> 1.1683903 | AF27: 3 | AG27: MDLZ | AH27: ='Quick Ratio'!D13 -> 0.48161031 | AI27: ='Quick Ratio'!C13 -> 0.42539315 | AJ27: ='Quick Ratio'!B13 -> 0.40105194
P28: 4 | Q28: TMUS | R28: ='Quick Ratio'!D21 -> 0.83260632 | S28: ='Quick Ratio'!C21 -> 0.8284117 | T28: ='Quick Ratio'!B21 -> 0.69448711 | AF28: 4 | AG28: KDP | AH28: ='Quick Ratio'!D12 -> 0.33362186 | AI28: ='Quick Ratio'!C12 -> 0.25044863 | AJ28: ='Quick Ratio'!B12 -> 0.30832095
A29: 4 | B29: Cash Ratio | H29: 4 | I29: Cash Ratio | P29: 5 | Q29: CHTR | R29: ='Quick Ratio'!D8 -> 0.31388106 | S29: ='Quick Ratio'!C8 -> 0.31269865 | T29: ='Quick Ratio'!B8 -> 0.33294654 | X29: 4 | Y29: Cash Ratio | AF29: 5 | AG29: CCEP | AH29: ='Quick Ratio'!D7 -> 0.61725365 | AI29: ='Quick Ratio'!C7 -> 0.72121462 | AJ29: ='Quick Ratio'!B7 -> 0.70600301
B30: Тикер | C30: 2024 | D30: 2023 | E30: 2022 | I30: Тикер | J30: 2024 | K30: 2023 | L30: 2022 | Y30: Тикер | Z30: 2024 | AA30: 2023 | AB30: 2022
A31: 1 | B31: AAPL | C31: ='Cash Ratio'!D2 -> 0.1697526 | D31: ='Cash Ratio'!C2 -> 0.20621714 | E31: ='Cash Ratio'!B2 -> 0.1535634 | H31: 1 | I31: AMZN | J31: ='Cash Ratio'!D5 -> 0.43904899 | K31: ='Cash Ratio'!C5 -> 0.44499354 | L31: ='Cash Ratio'!B5 -> 0.34678525 | X31: 1 | Y31: AMGN | Z31: ='Cash Ratio'!D4 -> 0.51833413 | AA31: ='Cash Ratio'!C4 -> 0.59504132 | AB31: ='Cash Ratio'!B4 -> 0.48632626
A32: 2 | B32: MSFT | C32: ='Cash Ratio'!D16 -> 0.14618553 | D32: ='Cash Ratio'!C16 -> 0.33321491 | E32: ='Cash Ratio'!B16 -> 0.14651564 | H32: 2 | I32: MELI | J32: ='Cash Ratio'!D14 -> 0.15870626 | K32: ='Cash Ratio'!C14 -> 0.22693776 | L32: ='Cash Ratio'!B14 -> 0.22307872 | P32: 4 | Q32: Cash Ratio | X32: 2 | Y32: REGN | Z32: ='Cash Ratio'!D20 -> 0.63083437 | AA32: ='Cash Ratio'!C20 -> 0.79745282 | AB32: ='Cash Ratio'!B20 -> 0.98873078 | AF32: 4 | AG32: Cash Ratio
A33: 3 | B33: ASML | C33: ='Cash Ratio'!D6 -> 0.63516263 | D33: ='Cash Ratio'!C6 -> 0.43040425 | E33: ='Cash Ratio'!B6 -> 0.40416268 | H33: 3 | I33: TSLA | J33: ='Cash Ratio'!D22 -> 0.55997363 | K33: ='Cash Ratio'!C22 -> 0.5704049 | L33: ='Cash Ratio'!B22 -> 0.60852147 | Q33: Тикер | R33: 2024 | S33: 2023 | T33: 2022 | X33: 3 | Y33: GILD | Z33: ='Cash Ratio'!D10 -> 0.8323059 | AA33: ='Cash Ratio'!C10 -> 0.53945035 | AB33: ='Cash Ratio'!B10 -> 0.48158035 | AG33: Тикер | AH33: 2024 | AI33: 2023 | AJ33: 2022
A34: 4 | B34: AMD | C34: ='Cash Ratio'!D3 -> 0.52012086 | D34: ='Cash Ratio'!C3 -> 0.58798027 | E34: ='Cash Ratio'!B3 -> 0.75914586 | H34: 4 | I34: PDD | J34: ='Cash Ratio'!D18 -> 0.3065873 | K34: ='Cash Ratio'!C18 -> 0.39106682 | L34: ='Cash Ratio'!B18 -> 0.29366366 | P34: 1 | Q34: GOOGL | R34: ='Cash Ratio'!D11 -> 0.26330199 | S34: ='Cash Ratio'!C11 -> 0.29393502 | T34: ='Cash Ratio'!B11 -> 0.31571429 | X34: 4 | Y34: VRTX | Z34: ='Cash Ratio'!D23 -> 1.2819391 | AA34: ='Cash Ratio'!C23 -> 2.923014 | AB34: ='Cash Ratio'!B23 -> 3.8306408 | AF34: 1 | AG34: COST | AH34: ='Cash Ratio'!D9 -> 0.27932551 | AI34: ='Cash Ratio'!C9 -> 0.4079445 | AJ34: ='Cash Ratio'!B9 -> 0.31886368
P35: 2 | Q35: META | R35: ='Cash Ratio'!D15 -> 1.3063758 | S35: ='Cash Ratio'!C15 -> 1.3098248 | T35: ='Cash Ratio'!B15 -> 0.54321764 | AF35: 2 | AG35: PEP | AH35: ='Cash Ratio'!D19 -> 0.26969178 | AI35: ='Cash Ratio'!C19 -> 0.30685373 | AJ35: ='Cash Ratio'!B19 -> 0.18495427
A36: Вывод | P36: 3 | Q36: NFLX | R36: ='Cash Ratio'!D17 -> 0.72565716 | S36: ='Cash Ratio'!C17 -> 0.80320394 | T36: ='Cash Ratio'!B17 -> 0.64899671 | AF36: 3 | AG36: MDLZ | AH36: ='Cash Ratio'!D13 -> 0.069108394 | AI36: ='Cash Ratio'!C13 -> 0.095198022 | AJ36: ='Cash Ratio'!B13 -> 0.11493635
P37: 4 | Q37: TMUS | R37: ='Cash Ratio'!D21 -> 0.26811738 | S37: ='Cash Ratio'!C21 -> 0.24536506 | T37: ='Cash Ratio'!B21 -> 0.18215989 | AF37: 4 | AG37: KDP | AH37: ='Cash Ratio'!D12 -> 0.063064177 | AI37: ='Cash Ratio'!C12 -> 0.029946164 | AJ37: ='Cash Ratio'!B12 -> 0.066245666
P38: 5 | Q38: CHTR | R38: ='Cash Ratio'!D8 -> 0.034035296 | S38: ='Cash Ratio'!C8 -> 0.053655214 | T38: ='Cash Ratio'!B8 -> 0.053460423 | AF38: 5 | AG38: CCEP | AH38: ='Cash Ratio'!D7 -> 0.19180268 | AI38: ='Cash Ratio'!C7 -> 0.19497115 | AJ38: ='Cash Ratio'!B7 -> 0.18966225
P40: Выводы: | X40: Выводы:
A41: По итогам анализа показателей финансовой устойчивости за 2022–2024 годы в данном блоке выбраны AMD и ASML. AMD демонстрирует отрицательный чистый долг (ND/EBITDA от -0.23 до -0.36) и лучшую ликвидность в группе (Current Ratio стабильно выше 2.36) на протяжении всего периода. ASML также показывает полное отсутствие долгового бремени (ND/EBITDA до -0.80) при уверенном росте показателей ликвидности (Current Ratio вырос с 1.28 до 1.53). Microsoft занимает среднюю позицию с умеренным долгом (ND/EBITDA не выше 0.47) и приемлемой ликвидностью, но уступает лидерам. Apple выбывает ввиду хронической нехватки ликвидности (Current и Quick Ratio стабильно ниже 1.0 все три года) и наибольшей в блоке долговой нагрузки (ND/EBITDA 0.57–0.83), что делает её аутсайдером по краткосрочной финансовой устойчивости. | H41: По итогам анализа показателей финансовой устойчивости в данном блоке выбраны PDD Holdings (PDD) и Tesla (TSLA). PDD демонстрирует отрицательный чистый долг (ND/EBITDA −0.35 в 2024 году) и лучшие показатели ликвидности в отрасли (Current Ratio 2.21, Quick Ratio 2.21), что свидетельствует о практически полном отсутствии долговой нагрузки и высоком краткосрочном запасе прочности. Tesla также имеет отрицательный чистый долг (ND/EBITDA −0.17 в 2024 году), причём этот показатель оставался отрицательным на протяжении всего трёхлетнего периода, а показатели ликвидности уверенно росли (Current Ratio вырос с 1.53 в 2022 до 2.02 в 2024 году, Cash Ratio устойчиво держится на уровне около 0.56–0.61). Amazon занимает промежуточную позицию: долговая нагрузка существенно снизилась с 2.25 в 2022 до 0.42 в 2024 году, однако Quick Ratio (0.87) остаётся ниже единицы, что ограничивает краткосрочную финансовую гибкость. MercadoLibre выбывает ввиду наибольшей в отрасли долговой нагрузки (ND/EBITDA 1.31 в 2024 году) и минимального Cash Ratio (0.16), что формирует относительно более высокие финансовые риски по сравнению с лидерами. | P41: По итогам анализа показателей финансовой устойчивости в данном блоке выбраны Alphabet/Google (GOOGL) и Meta (META). Alphabet демонстрирует практически нулевую долговую нагрузку (ND/EBITDA -0.01 в 2024 году) и высокую ликвидность (Current Ratio 1.84, Quick Ratio 1.81), что свидетельствует о полной финансовой независимости. Meta показывает исключительные показатели ликвидности в отрасли (Current Ratio 2.98, Cash Ratio 1.31) при минимальном долге (ND/EBITDA 0.06), что означает наличие значительного запаса денежных средств. Netflix занимает среднюю позицию с умеренной долговой нагрузкой и приемлемой ликвидностью выше 1.0, однако не является лидером ни по одному показателю блока. T-Mobile и Charter выбывают ввиду критически высокой закредитованности (ND/EBITDA 3.50 и 4.45 соответственно) и показателей ликвидности ниже нормы, что создаёт существенные финансовые риски. | X41: По итогам анализа показателей финансовой устойчивости за 2022 - 2024 годы в данном блоке выбраны Regeneron Pharmaceuticals (REGN) и Vertex Pharmaceuticals (VRTX). REGN демонстрирует отличную финансовую устойчивость: показатель ND/EBITDA равен практически нулю (0,04 в 2024 году, против -0,08 в 2022 году), компания фактически не имеет чистого долга. При этом ликвидность находится на лидирующем в группе уровне: Current Ratio = 4,73, Quick Ratio = 3,95, Cash Ratio = 0,63 в 2024 году являются самыми высокими значениями в отрасли, свидетельствующие о значительном запасе краткосрочной финансовой прочности. VRTX обладает наилучшим показателем ND/EBITDA в группе (-5,81 в 2024 году), компания является нетто-кредитором и располагает значительной денежной позицией, что обеспечивает абсолютную независимость от долгового финансирования. Показатели ликвидности VRTX также уверенно превышают норму (Current Ratio = 2,69, Cash Ratio = 1,28). AMGN и GILD выбывают по данному блоку ввиду высокой долговой нагрузки: ND/EBITDA AMGN составляет 3,60, у GILD 3,77 в 2024 году, что значительно превышает комфортный уровень для фармацевтического сектора и создает существенные риски при изменении процентных ставок или ухудшении операционных результатов. | AF41: По итогам анализа показателей финансовой устойчивости были отобраны Costco (COST) и PepsiCo (PEP). Costco имеет отрицательный ND/EBITDA (−0,14 в 2024 году), то есть денежные средства на балансе превышают долг, что говорит о высокой финансовой устойчивости. Компания также лидирует по Current Ratio (0,97) и Cash Ratio (0,28). Бизнес-модель Costco предполагает быструю оборачиваемость товаров и отсрочку платежей поставщикам, что создаёт отрицательный рабочий капитал при стабильном денежном потоке. PepsiCo демонстрирует умеренную и снижающуюся долговую нагрузку (ND/EBITDA снизился с 2,32 в 2022 году до 2,18 в 2024 году). Показатели Quick Ratio (0,65) и Cash Ratio (0,27) являются вторыми в группе, что подтверждает достаточную ликвидность для компании такого масштаба. KDP исключается из-за наихудших показателей (самый высокий долг ND/EBITDA = 4,45 и самая низкая ликвидность Current Ratio = 0,49, Quick Ratio = 0,33), что создаёт наибольший финансовый риск. Mondelez, несмотря на заметное снижение долга с 4,52 до 2,11, имеет минимальный Cash Ratio (0,07) в группе, что ограничивает финансовую гибкость компании.
A42: AMD | H42: PDD | P42: GOOGL | X42: REGN | AF42: COST
A43: ASML | H43: TSLA | P43: META | X43: VRTX | AF43: PEP

Sheet Агрегированный Итог
A3: Отрасль 1. Технологии и полупроводники. | F3: Отрасль 2. Потребительский discretionary, e-commerce и онлайн-сервисы. | O3: Отрасль 3. Коммуникационные сервисы, digital-реклама и подписки. | W3: Отрасль 4. Здравоохранение, биотехнологии и медицинские технологии. | AF3: Отрасль 5. Потребительские товары повседневного спроса.
A5: Рентабельность | F5: Рентабельность | O5: Рентабельность | W5: Рентабельность | AF5: Рентабельность
A6: AAPL | F6: PDD | O6: Лидеры - Alphabet/Google (GOOGL) и Meta (META) | W6: REGN | AF6: Лидеры - Costco Wholesale Corporation (COST) и Pepsico, Inc. (PEP)
A7: ASML | F7: MELI | W7: AMGN
A11: Мультипликаторы | F11: Мультипликаторы | O11: Мультипликаторы | W11: Мультипликаторы | AF11: Мультипликаторы
A12: AAPL | F12: PDD | O12: Лидеры по дешевизне оценки - Charter Communications (CHTR) и T-Mobile (TMUS) | W12: REGN | AF12: Лидеры - Coca-Cola Europacific Partners (CCEP) и Mondelez International, Inc. (MDLZ)
A13: ASML | F13: AMZN | W13: AMGN
F15: Показатели фин устойчивости | O15: Показатели фин устойчивости | W15: Показатели фин устойчивости | AF15: Показатели фин устойчивости
A16: Показатели фин устойчивости | F16: PDD | O16: лидеры - Alphabet/Google (GOOGL) и Meta (META) | W16: REGN | AF16: Лидеры - Costco Wholesale Corporation (COST) и Pepsico, Inc. (PEP)
A17: AMD | F17: TSLA | W17: VRTX
A18: ASML
A19: Итоговая рекомендация: | F19: Итоговая рекомендация: | O19: Итоговая рекомендация: | W19: Итоговая рекомендация: | AF19: Итоговая рекомендация:
A20: По результатам сравнительного анализа всех трёх блоков показателей в финальную выборку от отрасли "Технологии и полупроводники" проходят Apple (AAPL) и ASML Holding (ASML). Обе компании являются лидерами по рентабельности и привлекательности рыночной оценки, а низкая краткосрочная ликвидность Apple оправдана фундаментально сильным бизнесом и исключительной эффективностью использования капитала. Microsoft и AMD, несмотря на сильные показатели финансовой устойчивости, не прошли отбор ввиду отставания по отдаче на капитал у первой и критически низкой операционной эффективности при сильной переоценке рынком у второй. | F20: По результатам сравнительного анализа всех трёх блоков показателей в финальную выборку от отрасли «Потребительский discretionary, e-commerce и онлайн-сервисы» проходят PDD Holdings (PDD) и Amazon (AMZN). PDD является безусловным лидером отрасли по совокупности критериев: компания занимает первые позиции по рентабельности, обладает наиболее привлекательной рыночной оценкой и демонстрирует лучшие показатели финансовой устойчивости, неизменно занимая лидирующие позиции во всех трёх блоках анализа. Amazon проходит отбор как компания с наиболее сбалансированным профилем среди оставшихся претендентов: восстанавливающаяся и растущая рентабельность, умеренная рыночная оценка и управляемая долговая нагрузка. MercadoLibre, несмотря на лидерство по ROE и сильную динамику роста, не проходит отбор ввиду более дорогой рыночной оценки и более высокой долговой нагрузки. Tesla выбывает из-за сочетания устойчивого снижения рентабельности по всем метрикам и критически завышенных мультипликаторов, которые несовместимы с реальными финансовыми результатами компании. | O20: По результатам сравнительного анализа всех трёх блоков показателей в финальную выборку от отрасли "Коммуникационные сервисы, digital-реклама и подписки" проходят Alphabet/Google (GOOGL) и Meta Platforms (META). Обе компании являются лидерами по рентабельности и финансовой устойчивости, а их более высокая рыночная оценка относительно CHTR и TMUS оправдана фундаментально сильным бизнесом и высокой рентабельностью. Charter Communications и T-Mobile, несмотря на формально низкие мультипликаторы, не прошли отбор ввиду слабой операционной эффективности и высокой долговой нагрузки. | W20: По результатам сравнительного анализа всех трех блоков показателей в финальную выборку от отрасли «Здравоохранение, биотехнологии и медицинские технологии» были выбраны Regeneron Pharmaceuticals (REGN) и Amgen (AMGN). Regeneron является безусловным лидером отрасли по совокупности критериев: компания демонстрирует наиболее высокую рентабельность продаж в группе (31,1%), наиболее привлекательную рыночную оценку по P/E среди компаний с положительной прибылью (18,43x) и абсолютную финансовую устойчивость с практически нулевым чистым долгом и наивысшей ликвидностью в отрасли. AMGN также был выбран как компания с наиболее сбалансированным профилем среди оставшихся претендентов: лидерство по ROE, наименьший EV/EBITDA в группе (13,68x) и достаточный уровень ликвидности, несмотря на повышенную долговую нагрузку, оправданную масштабом и устойчивостью денежных потоков компании. GILD не проходит отбор ввиду резкого ухудшения всех показателей рентабельности в 2024 году и слишком высоких мультипликаторов, а VRTX из-за сочетания отрицательной рентабельности по итогам 2024 года и сильно завышенного EV/EBITDA, несмотря на лидирующую финансовую устойчивость. | AF20: По результатам анализа трех блоков показателей в финальную выборку по отрасли «Потребительские товары повседневного спроса» проходят Costco (COST) и PepsiCo (PEP). Обе компании входят в число лидеров по двум из трёх направлений. Costco показывает лучшие результаты по рентабельности (ROIC 25,48%, ROA 10,61%) и финансовой устойчивости (отрицательный ND/EBITDA). PepsiCo имеет самый высокий ROE в группе (52,42%) и умеренную, снижающуюся долговую нагрузку. Mondelez и CCEP отличаются наиболее низкими мультипликаторами (P/E, EV/EBITDA, P/S), но их рентабельность заметно ниже, чем у Costco и PepsiCo, а показатели финансовой устойчивости находятся на среднем уровне. Таким образом, их низкая рыночная оценка соответствует более скромным финансовым результатам, а не недооцененности.
AF21: COST
AF22: PEP

Sheet PEG
A1: Ticker | B1: 2024
A2: AAPL | B2: ='P E'!D2/'Summary (up to 2024)'!F2 -> -16650.045
A3: AMD | B3: ='P E'!D3/'Summary (up to 2024)'!F3 -> 1326.0592
A4: AMGN | B4: ='P E'!D4/'Summary (up to 2024)'!F4 -> -156.8032 | E4: PEG = P E/EPS growth rate
A5: AMZN
A6: ASML | B6: ='P E'!D6/'Summary (up to 2024)'!F6 -> 377.4867
A7: CCEP | B7: ='P E'!D7/'Summary (up to 2024)'!F7 -> -741.05925
A8: CHTR | B8: ='P E'!D8/'Summary (up to 2024)'!F8 -> 147.20553
A9: COST | B9: ='P E'!D9/'Summary (up to 2024)'!F9 -> 447.63244
A10: GILD | B10: ='P E'!D10/'Summary (up to 2024)'!F10 -> -347.3687
A11: GOOGL | B11: ='P E'!D11/'Summary (up to 2024)'!F11 -> 71.487486
A12: KDP | B12: ='P E'!D12/'Summary (up to 2024)'!F12 -> 1488.3421
A13: MDLZ | B13: ='P E'!D13/'Summary (up to 2024)'!F13 -> 52.297749
A14: MELI | B14: ='P E'!D14/'Summary (up to 2024)'!F14 -> 45.632679
A15: META | B15: ='P E'!D15/'Summary (up to 2024)'!F15 -> 36.664131
A16: MSFT | B16: ='P E'!D16/'Summary (up to 2024)'!F16 -> 333.657
